{
  "nbformat": 4,
  "nbformat_minor": 0,
  "metadata": {
    "colab": {
      "provenance": [],
      "include_colab_link": true
    },
    "kernelspec": {
      "name": "python3",
      "display_name": "Python 3"
    },
    "language_info": {
      "name": "python"
    }
  },
  "cells": [
    {
      "cell_type": "markdown",
      "metadata": {
        "id": "view-in-github",
        "colab_type": "text"
      },
      "source": [
        "<a href=\"https://colab.research.google.com/github/abhi-ar17/BDD-Framework/blob/master/DBMS.ipynb\" target=\"_parent\"><img src=\"https://colab.research.google.com/assets/colab-badge.svg\" alt=\"Open In Colab\"/></a>"
      ]
    },
    {
      "cell_type": "code",
      "execution_count": null,
      "metadata": {
        "id": "E89Ap0HMTaDh"
      },
      "outputs": [],
      "source": [
        "pip install Django\n"
      ]
    },
    {
      "cell_type": "code",
      "source": [
        "!unzip employee_database\\ \\(4\\).zip"
      ],
      "metadata": {
        "id": "Ru2eT258Th9j"
      },
      "execution_count": null,
      "outputs": []
    },
    {
      "cell_type": "code",
      "source": [
        "pip install djongo\n"
      ],
      "metadata": {
        "id": "MhGxEILorN0l"
      },
      "execution_count": null,
      "outputs": []
    },
    {
      "cell_type": "code",
      "source": [
        "pip install pymongo"
      ],
      "metadata": {
        "colab": {
          "base_uri": "https://localhost:8080/"
        },
        "id": "ycTqkEG7Dr6-",
        "outputId": "9d0aed3b-c42c-4592-8879-bee57f4f28cf"
      },
      "execution_count": null,
      "outputs": [
        {
          "output_type": "stream",
          "name": "stdout",
          "text": [
            "Looking in indexes: https://pypi.org/simple, https://us-python.pkg.dev/colab-wheels/public/simple/\n",
            "Requirement already satisfied: pymongo in /usr/local/lib/python3.8/dist-packages (4.3.3)\n",
            "Requirement already satisfied: dnspython<3.0.0,>=1.16.0 in /usr/local/lib/python3.8/dist-packages (from pymongo) (2.3.0)\n"
          ]
        }
      ]
    },
    {
      "cell_type": "code",
      "source": [
        "!django-admin startproject myproject\n",
        "!django-admin startproject employee_database\n",
        "!cd employee_database && python manage.py startapp PersonalData"
      ],
      "metadata": {
        "id": "dWMzPuDOqc0K"
      },
      "execution_count": null,
      "outputs": []
    },
    {
      "cell_type": "code",
      "source": [
        "!wget https://bin.equinox.io/c/4VmDzA7iaHb/ngrok-stable-linux-amd64.zip\n",
        "!unzip ngrok-stable-linux-amd64.zip"
      ],
      "metadata": {
        "id": "a2pau9LBJMzt"
      },
      "execution_count": null,
      "outputs": []
    },
    {
      "cell_type": "code",
      "source": [
        "!./ngrok authtoken 2MEzmBMheTKErpD1YMYY5nybALk_52hzkR9ufnSPj9PABqDtc"
      ],
      "metadata": {
        "colab": {
          "base_uri": "https://localhost:8080/"
        },
        "id": "uECENs-kJXX8",
        "outputId": "4373b53f-70fe-487c-a825-c1cd68905849"
      },
      "execution_count": 14,
      "outputs": [
        {
          "output_type": "stream",
          "name": "stdout",
          "text": [
            "Authtoken saved to configuration file: /root/.ngrok2/ngrok.yml\n"
          ]
        }
      ]
    },
    {
      "cell_type": "code",
      "source": [
        "!pip install pyngrok\n",
        "from pyngrok import ngrok\n",
        "\n",
        "# Start ngrok tunnel\n",
        "public_url = ngrok.connect(port=80,http_tunnel=False)\n",
        "print(public_url)"
      ],
      "metadata": {
        "colab": {
          "base_uri": "https://localhost:8080/"
        },
        "id": "q5W2U5CXBPmT",
        "outputId": "7713f828-49df-4363-ba5c-a7c0a3e9eea5"
      },
      "execution_count": 5,
      "outputs": [
        {
          "output_type": "stream",
          "name": "stdout",
          "text": [
            "Looking in indexes: https://pypi.org/simple, https://us-python.pkg.dev/colab-wheels/public/simple/\n",
            "Requirement already satisfied: pyngrok in /usr/local/lib/python3.9/dist-packages (5.2.1)\n",
            "Requirement already satisfied: PyYAML in /usr/local/lib/python3.9/dist-packages (from pyngrok) (6.0)\n",
            "NgrokTunnel: \"http://3d00-130-211-241-8.ngrok.io\" -> \"http://localhost:80\"\n"
          ]
        }
      ]
    },
    {
      "cell_type": "code",
      "source": [
        "!cd employee_database && python manage.py makemigrations PersonalData\n"
      ],
      "metadata": {
        "colab": {
          "base_uri": "https://localhost:8080/"
        },
        "id": "4_URqI8uXya6",
        "outputId": "01871a7b-b87a-49b0-ff59-633908c5dc85"
      },
      "execution_count": 9,
      "outputs": [
        {
          "output_type": "stream",
          "name": "stdout",
          "text": [
            "No changes detected in app 'PersonalData'\n"
          ]
        }
      ]
    },
    {
      "cell_type": "code",
      "source": [
        "!cd employee_database && python manage.py migrate\n"
      ],
      "metadata": {
        "colab": {
          "base_uri": "https://localhost:8080/"
        },
        "id": "vy1imaX9YSck",
        "outputId": "a4890081-3d4e-4f5b-9aee-097772413c32"
      },
      "execution_count": 10,
      "outputs": [
        {
          "output_type": "stream",
          "name": "stdout",
          "text": [
            "\u001b[36;1mOperations to perform:\u001b[0m\n",
            "\u001b[1m  Apply all migrations: \u001b[0mPersonalData, admin, auth, contenttypes, sessions\n",
            "\u001b[36;1mRunning migrations:\u001b[0m\n",
            "  No migrations to apply.\n"
          ]
        }
      ]
    },
    {
      "cell_type": "code",
      "source": [
        "!cd employee_database && python manage.py runserver 127.0.0.1:80"
      ],
      "metadata": {
        "colab": {
          "base_uri": "https://localhost:8080/"
        },
        "id": "1QkU6l2IDcWy",
        "outputId": "17623250-6b4f-42c8-d0df-2bba48469c77"
      },
      "execution_count": 6,
      "outputs": [
        {
          "output_type": "stream",
          "name": "stdout",
          "text": [
            "[18/Mar/2023 19:09:44] \u001b[m\"GET /employee/create/ HTTP/1.1\" 200 2622\u001b[0m\n",
            "[18/Mar/2023 19:10:15] \u001b[m\"POST /employee/create/ HTTP/1.1\" 200 2779\u001b[0m\n",
            "/content/employee_database/PersonalData/models.py changed, reloading.\n",
            "Watching for file changes with StatReloader\n",
            "Performing system checks...\n",
            "\n",
            "System check identified no issues (0 silenced).\n",
            "March 18, 2023 - 19:10:41\n",
            "Django version 4.1.7, using settings 'employee_database.settings'\n",
            "Starting development server at http://127.0.0.1:80/\n",
            "Quit the server with CONTROL-C.\n",
            "/content/employee_database/PersonalData/models.py changed, reloading.\n",
            "Watching for file changes with StatReloader\n",
            "Performing system checks...\n",
            "\n",
            "System check identified no issues (0 silenced).\n",
            "March 18, 2023 - 19:11:29\n",
            "Django version 4.1.7, using settings 'employee_database.settings'\n",
            "Starting development server at http://127.0.0.1:80/\n",
            "Quit the server with CONTROL-C.\n",
            "/content/employee_database/PersonalData/forms.py changed, reloading.\n",
            "Watching for file changes with StatReloader\n",
            "Performing system checks...\n",
            "\n",
            "Exception in thread django-main-thread:\n",
            "Traceback (most recent call last):\n",
            "  File \"/usr/lib/python3.9/threading.py\", line 980, in _bootstrap_inner\n",
            "    self.run()\n",
            "  File \"/usr/lib/python3.9/threading.py\", line 917, in run\n",
            "    self._target(*self._args, **self._kwargs)\n",
            "  File \"/usr/local/lib/python3.9/dist-packages/django/utils/autoreload.py\", line 64, in wrapper\n",
            "    fn(*args, **kwargs)\n",
            "  File \"/usr/local/lib/python3.9/dist-packages/django/core/management/commands/runserver.py\", line 134, in inner_run\n",
            "    self.check(display_num_errors=True)\n",
            "  File \"/usr/local/lib/python3.9/dist-packages/django/core/management/base.py\", line 475, in check\n",
            "    all_issues = checks.run_checks(\n",
            "  File \"/usr/local/lib/python3.9/dist-packages/django/core/checks/registry.py\", line 88, in run_checks\n",
            "    new_errors = check(app_configs=app_configs, databases=databases)\n",
            "  File \"/usr/local/lib/python3.9/dist-packages/django/core/checks/urls.py\", line 14, in check_url_config\n",
            "    return check_resolver(resolver)\n",
            "  File \"/usr/local/lib/python3.9/dist-packages/django/core/checks/urls.py\", line 24, in check_resolver\n",
            "    return check_method()\n",
            "  File \"/usr/local/lib/python3.9/dist-packages/django/urls/resolvers.py\", line 494, in check\n",
            "    for pattern in self.url_patterns:\n",
            "  File \"/usr/local/lib/python3.9/dist-packages/django/utils/functional.py\", line 57, in __get__\n",
            "    res = instance.__dict__[self.name] = self.func(instance)\n",
            "  File \"/usr/local/lib/python3.9/dist-packages/django/urls/resolvers.py\", line 715, in url_patterns\n",
            "    patterns = getattr(self.urlconf_module, \"urlpatterns\", self.urlconf_module)\n",
            "  File \"/usr/local/lib/python3.9/dist-packages/django/utils/functional.py\", line 57, in __get__\n",
            "    res = instance.__dict__[self.name] = self.func(instance)\n",
            "  File \"/usr/local/lib/python3.9/dist-packages/django/urls/resolvers.py\", line 708, in urlconf_module\n",
            "    return import_module(self.urlconf_name)\n",
            "  File \"/usr/lib/python3.9/importlib/__init__.py\", line 127, in import_module\n",
            "    return _bootstrap._gcd_import(name[level:], package, level)\n",
            "  File \"<frozen importlib._bootstrap>\", line 1030, in _gcd_import\n",
            "  File \"<frozen importlib._bootstrap>\", line 1007, in _find_and_load\n",
            "  File \"<frozen importlib._bootstrap>\", line 986, in _find_and_load_unlocked\n",
            "  File \"<frozen importlib._bootstrap>\", line 680, in _load_unlocked\n",
            "  File \"<frozen importlib._bootstrap_external>\", line 850, in exec_module\n",
            "  File \"<frozen importlib._bootstrap>\", line 228, in _call_with_frames_removed\n",
            "  File \"/content/employee_database/employee_database/urls.py\", line 18, in <module>\n",
            "    from PersonalData.views import employee_create\n",
            "  File \"/content/employee_database/PersonalData/views.py\", line 3, in <module>\n",
            "    from .forms import EmployeeForm\n",
            "  File \"/content/employee_database/PersonalData/forms.py\", line 14, in <module>\n",
            "    class EmployeeForm(forms.ModelForm):\n",
            "  File \"/content/employee_database/PersonalData/forms.py\", line 20, in EmployeeForm\n",
            "    class Meta:\n",
            "  File \"/content/employee_database/PersonalData/forms.py\", line 24, in Meta\n",
            "    'dob': widgets.DateInput(attrs={'type': 'date'})\n",
            "NameError: name 'widgets' is not defined\n",
            "/content/employee_database/PersonalData/forms.py changed, reloading.\n",
            "Watching for file changes with StatReloader\n",
            "Performing system checks...\n",
            "\n",
            "Exception in thread django-main-thread:\n",
            "Traceback (most recent call last):\n",
            "  File \"/usr/lib/python3.9/threading.py\", line 980, in _bootstrap_inner\n",
            "    self.run()\n",
            "  File \"/usr/lib/python3.9/threading.py\", line 917, in run\n",
            "    self._target(*self._args, **self._kwargs)\n",
            "  File \"/usr/local/lib/python3.9/dist-packages/django/utils/autoreload.py\", line 64, in wrapper\n",
            "    fn(*args, **kwargs)\n",
            "  File \"/usr/local/lib/python3.9/dist-packages/django/core/management/commands/runserver.py\", line 134, in inner_run\n",
            "    self.check(display_num_errors=True)\n",
            "  File \"/usr/local/lib/python3.9/dist-packages/django/core/management/base.py\", line 475, in check\n",
            "    all_issues = checks.run_checks(\n",
            "  File \"/usr/local/lib/python3.9/dist-packages/django/core/checks/registry.py\", line 88, in run_checks\n",
            "    new_errors = check(app_configs=app_configs, databases=databases)\n",
            "  File \"/usr/local/lib/python3.9/dist-packages/django/core/checks/urls.py\", line 14, in check_url_config\n",
            "    return check_resolver(resolver)\n",
            "  File \"/usr/local/lib/python3.9/dist-packages/django/core/checks/urls.py\", line 24, in check_resolver\n",
            "    return check_method()\n",
            "  File \"/usr/local/lib/python3.9/dist-packages/django/urls/resolvers.py\", line 494, in check\n",
            "    for pattern in self.url_patterns:\n",
            "  File \"/usr/local/lib/python3.9/dist-packages/django/utils/functional.py\", line 57, in __get__\n",
            "    res = instance.__dict__[self.name] = self.func(instance)\n",
            "  File \"/usr/local/lib/python3.9/dist-packages/django/urls/resolvers.py\", line 715, in url_patterns\n",
            "    patterns = getattr(self.urlconf_module, \"urlpatterns\", self.urlconf_module)\n",
            "  File \"/usr/local/lib/python3.9/dist-packages/django/utils/functional.py\", line 57, in __get__\n",
            "    res = instance.__dict__[self.name] = self.func(instance)\n",
            "  File \"/usr/local/lib/python3.9/dist-packages/django/urls/resolvers.py\", line 708, in urlconf_module\n",
            "    return import_module(self.urlconf_name)\n",
            "  File \"/usr/lib/python3.9/importlib/__init__.py\", line 127, in import_module\n",
            "    return _bootstrap._gcd_import(name[level:], package, level)\n",
            "  File \"<frozen importlib._bootstrap>\", line 1030, in _gcd_import\n",
            "  File \"<frozen importlib._bootstrap>\", line 1007, in _find_and_load\n",
            "  File \"<frozen importlib._bootstrap>\", line 986, in _find_and_load_unlocked\n",
            "  File \"<frozen importlib._bootstrap>\", line 680, in _load_unlocked\n",
            "  File \"<frozen importlib._bootstrap_external>\", line 850, in exec_module\n",
            "  File \"<frozen importlib._bootstrap>\", line 228, in _call_with_frames_removed\n",
            "  File \"/content/employee_database/employee_database/urls.py\", line 18, in <module>\n",
            "    from PersonalData.views import employee_create\n",
            "  File \"/content/employee_database/PersonalData/views.py\", line 3, in <module>\n",
            "    from .forms import EmployeeForm\n",
            "  File \"/content/employee_database/PersonalData/forms.py\", line 14, in <module>\n",
            "    class EmployeeForm(forms.ModelForm):\n",
            "  File \"/content/employee_database/PersonalData/forms.py\", line 20, in EmployeeForm\n",
            "    class Meta:\n",
            "  File \"/content/employee_database/PersonalData/forms.py\", line 24, in Meta\n",
            "    'dob': widgets.DateInput(attrs={'type': 'date'})\n",
            "NameError: name 'widgets' is not defined\n",
            "/content/employee_database/PersonalData/forms.py changed, reloading.\n",
            "Watching for file changes with StatReloader\n",
            "Performing system checks...\n",
            "\n",
            "System check identified no issues (0 silenced).\n",
            "March 18, 2023 - 19:12:02\n",
            "Django version 4.1.7, using settings 'employee_database.settings'\n",
            "Starting development server at http://127.0.0.1:80/\n",
            "Quit the server with CONTROL-C.\n",
            "/content/employee_database/PersonalData/forms.py changed, reloading.\n",
            "Watching for file changes with StatReloader\n",
            "Performing system checks...\n",
            "\n",
            "System check identified no issues (0 silenced).\n",
            "March 18, 2023 - 19:12:06\n",
            "Django version 4.1.7, using settings 'employee_database.settings'\n",
            "Starting development server at http://127.0.0.1:80/\n",
            "Quit the server with CONTROL-C.\n",
            "[18/Mar/2023 19:12:10] \u001b[m\"POST /employee/create/ HTTP/1.1\" 200 2779\u001b[0m\n",
            "Internal Server Error: /employee/create/\n",
            "Traceback (most recent call last):\n",
            "  File \"/usr/local/lib/python3.9/dist-packages/django/core/handlers/exception.py\", line 56, in inner\n",
            "    response = get_response(request)\n",
            "  File \"/usr/local/lib/python3.9/dist-packages/django/core/handlers/base.py\", line 197, in _get_response\n",
            "    response = wrapped_callback(request, *callback_args, **callback_kwargs)\n",
            "  File \"/content/employee_database/PersonalData/views.py\", line 28, in employee_create\n",
            "    primaryContact=form.cleaned_data['primaryContact'],\n",
            "KeyError: 'primaryContact'\n",
            "[18/Mar/2023 19:12:24] \u001b[35;1m\"POST /employee/create/ HTTP/1.1\" 500 72983\u001b[0m\n",
            "[18/Mar/2023 19:13:04] \u001b[m\"GET /employee/create/ HTTP/1.1\" 200 2622\u001b[0m\n",
            "Internal Server Error: /employee/create/\n",
            "Traceback (most recent call last):\n",
            "  File \"/usr/local/lib/python3.9/dist-packages/django/core/handlers/exception.py\", line 56, in inner\n",
            "    response = get_response(request)\n",
            "  File \"/usr/local/lib/python3.9/dist-packages/django/core/handlers/base.py\", line 197, in _get_response\n",
            "    response = wrapped_callback(request, *callback_args, **callback_kwargs)\n",
            "  File \"/content/employee_database/PersonalData/views.py\", line 28, in employee_create\n",
            "    primaryContact=form.cleaned_data['primaryContact'],\n",
            "KeyError: 'primaryContact'\n",
            "[18/Mar/2023 19:13:40] \u001b[35;1m\"POST /employee/create/ HTTP/1.1\" 500 72949\u001b[0m\n",
            "/content/employee_database/PersonalData/views.py changed, reloading.\n",
            "Watching for file changes with StatReloader\n",
            "Performing system checks...\n",
            "\n",
            "System check identified no issues (0 silenced).\n",
            "March 18, 2023 - 19:14:33\n",
            "Django version 4.1.7, using settings 'employee_database.settings'\n",
            "Starting development server at http://127.0.0.1:80/\n",
            "Quit the server with CONTROL-C.\n",
            "/content/employee_database/PersonalData/views.py changed, reloading.\n",
            "Watching for file changes with StatReloader\n",
            "Performing system checks...\n",
            "\n",
            "System check identified no issues (0 silenced).\n",
            "March 18, 2023 - 19:14:35\n",
            "Django version 4.1.7, using settings 'employee_database.settings'\n",
            "Starting development server at http://127.0.0.1:80/\n",
            "Quit the server with CONTROL-C.\n",
            "/content/employee_database/PersonalData/views.py changed, reloading.\n",
            "Watching for file changes with StatReloader\n",
            "Performing system checks...\n",
            "\n",
            "System check identified no issues (0 silenced).\n",
            "March 18, 2023 - 19:14:38\n",
            "Django version 4.1.7, using settings 'employee_database.settings'\n",
            "Starting development server at http://127.0.0.1:80/\n",
            "Quit the server with CONTROL-C.\n",
            "Internal Server Error: /employee/create/\n",
            "Traceback (most recent call last):\n",
            "  File \"/usr/local/lib/python3.9/dist-packages/django/core/handlers/exception.py\", line 56, in inner\n",
            "    response = get_response(request)\n",
            "  File \"/usr/local/lib/python3.9/dist-packages/django/core/handlers/base.py\", line 197, in _get_response\n",
            "    response = wrapped_callback(request, *callback_args, **callback_kwargs)\n",
            "  File \"/content/employee_database/PersonalData/views.py\", line 39, in employee_create\n",
            "    employee.save()\n",
            "NameError: name 'employee' is not defined\n",
            "[18/Mar/2023 19:14:39] \u001b[35;1m\"POST /employee/create/ HTTP/1.1\" 500 72928\u001b[0m\n",
            "Internal Server Error: /employee/create/\n",
            "Traceback (most recent call last):\n",
            "  File \"/usr/local/lib/python3.9/dist-packages/django/core/handlers/exception.py\", line 56, in inner\n",
            "    response = get_response(request)\n",
            "  File \"/usr/local/lib/python3.9/dist-packages/django/core/handlers/base.py\", line 197, in _get_response\n",
            "    response = wrapped_callback(request, *callback_args, **callback_kwargs)\n",
            "  File \"/content/employee_database/PersonalData/views.py\", line 39, in employee_create\n",
            "    employee.save()\n",
            "NameError: name 'employee' is not defined\n",
            "[18/Mar/2023 19:14:46] \u001b[35;1m\"POST /employee/create/ HTTP/1.1\" 500 72928\u001b[0m\n",
            "/content/employee_database/PersonalData/views.py changed, reloading.\n",
            "Watching for file changes with StatReloader\n",
            "Performing system checks...\n",
            "\n",
            "System check identified no issues (0 silenced).\n",
            "March 18, 2023 - 19:14:59\n",
            "Django version 4.1.7, using settings 'employee_database.settings'\n",
            "Starting development server at http://127.0.0.1:80/\n",
            "Quit the server with CONTROL-C.\n",
            "[18/Mar/2023 19:15:01] \u001b[32m\"GET /employee/create HTTP/1.1\" 301 0\u001b[0m\n",
            "[18/Mar/2023 19:15:01] \u001b[m\"GET /employee/create/ HTTP/1.1\" 200 2622\u001b[0m\n",
            "Internal Server Error: /employee/create/\n",
            "Traceback (most recent call last):\n",
            "  File \"/usr/local/lib/python3.9/dist-packages/django/core/handlers/exception.py\", line 56, in inner\n",
            "    response = get_response(request)\n",
            "  File \"/usr/local/lib/python3.9/dist-packages/django/core/handlers/base.py\", line 197, in _get_response\n",
            "    response = wrapped_callback(request, *callback_args, **callback_kwargs)\n",
            "  File \"/content/employee_database/PersonalData/views.py\", line 39, in employee_create\n",
            "    employee.save()\n",
            "NameError: name 'employee' is not defined\n",
            "[18/Mar/2023 19:15:21] \u001b[35;1m\"POST /employee/create/ HTTP/1.1\" 500 72880\u001b[0m\n",
            "/content/employee_database/PersonalData/views.py changed, reloading.\n",
            "Watching for file changes with StatReloader\n",
            "Performing system checks...\n",
            "\n",
            "System check identified no issues (0 silenced).\n",
            "March 18, 2023 - 19:15:53\n",
            "Django version 4.1.7, using settings 'employee_database.settings'\n",
            "Starting development server at http://127.0.0.1:80/\n",
            "Quit the server with CONTROL-C.\n",
            "/content/employee_database/PersonalData/views.py changed, reloading.\n",
            "Watching for file changes with StatReloader\n",
            "Performing system checks...\n",
            "\n",
            "System check identified no issues (0 silenced).\n",
            "March 18, 2023 - 19:15:57\n",
            "Django version 4.1.7, using settings 'employee_database.settings'\n",
            "Starting development server at http://127.0.0.1:80/\n",
            "Quit the server with CONTROL-C.\n",
            "[18/Mar/2023 19:15:58] \u001b[m\"GET /employee/create/ HTTP/1.1\" 200 2622\u001b[0m\n",
            "Internal Server Error: /employee/create/\n",
            "Traceback (most recent call last):\n",
            "  File \"/usr/local/lib/python3.9/dist-packages/django/core/handlers/exception.py\", line 56, in inner\n",
            "    response = get_response(request)\n",
            "  File \"/usr/local/lib/python3.9/dist-packages/django/core/handlers/base.py\", line 197, in _get_response\n",
            "    response = wrapped_callback(request, *callback_args, **callback_kwargs)\n",
            "  File \"/content/employee_database/PersonalData/views.py\", line 39, in employee_create\n",
            "    form.save()\n",
            "  File \"/content/employee_database/PersonalData/forms.py\", line 29, in save\n",
            "    emergency_contact = self.cleaned_data['emergency_contact']\n",
            "KeyError: 'emergency_contact'\n",
            "[18/Mar/2023 19:16:28] \u001b[35;1m\"POST /employee/create/ HTTP/1.1\" 500 77096\u001b[0m\n",
            "/content/employee_database/PersonalData/views.py changed, reloading.\n",
            "Watching for file changes with StatReloader\n",
            "Performing system checks...\n",
            "\n",
            "System check identified no issues (0 silenced).\n",
            "March 18, 2023 - 19:16:52\n",
            "Django version 4.1.7, using settings 'employee_database.settings'\n",
            "Starting development server at http://127.0.0.1:80/\n",
            "Quit the server with CONTROL-C.\n",
            "[18/Mar/2023 19:33:29] \u001b[m\"GET /employee/create/ HTTP/1.1\" 200 2622\u001b[0m\n",
            "Internal Server Error: /employee/create/\n",
            "Traceback (most recent call last):\n",
            "  File \"/usr/local/lib/python3.9/dist-packages/django/core/handlers/exception.py\", line 56, in inner\n",
            "    response = get_response(request)\n",
            "  File \"/usr/local/lib/python3.9/dist-packages/django/core/handlers/base.py\", line 197, in _get_response\n",
            "    response = wrapped_callback(request, *callback_args, **callback_kwargs)\n",
            "  File \"/content/employee_database/PersonalData/views.py\", line 39, in employee_create\n",
            "    form.save()\n",
            "  File \"/content/employee_database/PersonalData/forms.py\", line 29, in save\n",
            "    emergency_contact = self.cleaned_data['emergency_contact']\n",
            "KeyError: 'emergency_contact'\n",
            "[18/Mar/2023 19:33:56] \u001b[35;1m\"POST /employee/create/ HTTP/1.1\" 500 77101\u001b[0m\n",
            "/content/employee_database/PersonalData/forms.py changed, reloading.\n",
            "Watching for file changes with StatReloader\n",
            "Performing system checks...\n",
            "\n",
            "System check identified no issues (0 silenced).\n",
            "March 18, 2023 - 19:34:13\n",
            "Django version 4.1.7, using settings 'employee_database.settings'\n",
            "Starting development server at http://127.0.0.1:80/\n",
            "Quit the server with CONTROL-C.\n",
            "/content/employee_database/PersonalData/forms.py changed, reloading.\n",
            "Watching for file changes with StatReloader\n",
            "Performing system checks...\n",
            "\n",
            "System check identified no issues (0 silenced).\n",
            "March 18, 2023 - 19:34:18\n",
            "Django version 4.1.7, using settings 'employee_database.settings'\n",
            "Starting development server at http://127.0.0.1:80/\n",
            "Quit the server with CONTROL-C.\n",
            "/content/employee_database/PersonalData/forms.py changed, reloading.\n",
            "Watching for file changes with StatReloader\n",
            "Performing system checks...\n",
            "\n",
            "System check identified no issues (0 silenced).\n",
            "March 18, 2023 - 19:34:32\n",
            "Django version 4.1.7, using settings 'employee_database.settings'\n",
            "Starting development server at http://127.0.0.1:80/\n",
            "Quit the server with CONTROL-C.\n",
            "/content/employee_database/PersonalData/forms.py changed, reloading.\n",
            "Watching for file changes with StatReloader\n",
            "Performing system checks...\n",
            "\n",
            "System check identified no issues (0 silenced).\n",
            "March 18, 2023 - 19:35:28\n",
            "Django version 4.1.7, using settings 'employee_database.settings'\n",
            "Starting development server at http://127.0.0.1:80/\n",
            "Quit the server with CONTROL-C.\n",
            "/content/employee_database/PersonalData/forms.py changed, reloading.\n",
            "Watching for file changes with StatReloader\n",
            "Performing system checks...\n",
            "\n",
            "System check identified no issues (0 silenced).\n",
            "March 18, 2023 - 19:35:34\n",
            "Django version 4.1.7, using settings 'employee_database.settings'\n",
            "Starting development server at http://127.0.0.1:80/\n",
            "Quit the server with CONTROL-C.\n",
            "/content/employee_database/PersonalData/forms.py changed, reloading.\n",
            "Watching for file changes with StatReloader\n",
            "Performing system checks...\n",
            "\n",
            "System check identified no issues (0 silenced).\n",
            "March 18, 2023 - 19:35:36\n",
            "Django version 4.1.7, using settings 'employee_database.settings'\n",
            "Starting development server at http://127.0.0.1:80/\n",
            "Quit the server with CONTROL-C.\n",
            "[18/Mar/2023 19:35:39] \u001b[m\"GET /employee/create/ HTTP/1.1\" 200 2622\u001b[0m\n",
            "[18/Mar/2023 19:35:43] \u001b[m\"GET /employee/create/ HTTP/1.1\" 200 2622\u001b[0m\n",
            "Internal Server Error: /employee/create/\n",
            "Traceback (most recent call last):\n",
            "  File \"/usr/local/lib/python3.9/dist-packages/django/core/handlers/exception.py\", line 56, in inner\n",
            "    response = get_response(request)\n",
            "  File \"/usr/local/lib/python3.9/dist-packages/django/core/handlers/base.py\", line 197, in _get_response\n",
            "    response = wrapped_callback(request, *callback_args, **callback_kwargs)\n",
            "  File \"/content/employee_database/PersonalData/views.py\", line 39, in employee_create\n",
            "    form.save()\n",
            "  File \"/content/employee_database/PersonalData/forms.py\", line 29, in save\n",
            "    emergency_contact = self.cleaned_data['emergency_contact-0']\n",
            "KeyError: 'emergency_contact-0'\n",
            "[18/Mar/2023 19:36:08] \u001b[35;1m\"POST /employee/create/ HTTP/1.1\" 500 77119\u001b[0m\n",
            "/content/employee_database/PersonalData/forms.py changed, reloading.\n",
            "Watching for file changes with StatReloader\n",
            "Performing system checks...\n",
            "\n",
            "System check identified no issues (0 silenced).\n",
            "March 18, 2023 - 19:37:10\n",
            "Django version 4.1.7, using settings 'employee_database.settings'\n",
            "Starting development server at http://127.0.0.1:80/\n",
            "Quit the server with CONTROL-C.\n",
            "/content/employee_database/PersonalData/forms.py changed, reloading.\n",
            "Watching for file changes with StatReloader\n",
            "Performing system checks...\n",
            "\n",
            "Exception in thread django-main-thread:\n",
            "Traceback (most recent call last):\n",
            "  File \"/usr/lib/python3.9/threading.py\", line 980, in _bootstrap_inner\n",
            "    self.run()\n",
            "  File \"/usr/lib/python3.9/threading.py\", line 917, in run\n",
            "    self._target(*self._args, **self._kwargs)\n",
            "  File \"/usr/local/lib/python3.9/dist-packages/django/utils/autoreload.py\", line 64, in wrapper\n",
            "    fn(*args, **kwargs)\n",
            "  File \"/usr/local/lib/python3.9/dist-packages/django/core/management/commands/runserver.py\", line 134, in inner_run\n",
            "    self.check(display_num_errors=True)\n",
            "  File \"/usr/local/lib/python3.9/dist-packages/django/core/management/base.py\", line 475, in check\n",
            "    all_issues = checks.run_checks(\n",
            "  File \"/usr/local/lib/python3.9/dist-packages/django/core/checks/registry.py\", line 88, in run_checks\n",
            "    new_errors = check(app_configs=app_configs, databases=databases)\n",
            "  File \"/usr/local/lib/python3.9/dist-packages/django/core/checks/urls.py\", line 14, in check_url_config\n",
            "    return check_resolver(resolver)\n",
            "  File \"/usr/local/lib/python3.9/dist-packages/django/core/checks/urls.py\", line 24, in check_resolver\n",
            "    return check_method()\n",
            "  File \"/usr/local/lib/python3.9/dist-packages/django/urls/resolvers.py\", line 494, in check\n",
            "    for pattern in self.url_patterns:\n",
            "  File \"/usr/local/lib/python3.9/dist-packages/django/utils/functional.py\", line 57, in __get__\n",
            "    res = instance.__dict__[self.name] = self.func(instance)\n",
            "  File \"/usr/local/lib/python3.9/dist-packages/django/urls/resolvers.py\", line 715, in url_patterns\n",
            "    patterns = getattr(self.urlconf_module, \"urlpatterns\", self.urlconf_module)\n",
            "  File \"/usr/local/lib/python3.9/dist-packages/django/utils/functional.py\", line 57, in __get__\n",
            "    res = instance.__dict__[self.name] = self.func(instance)\n",
            "  File \"/usr/local/lib/python3.9/dist-packages/django/urls/resolvers.py\", line 708, in urlconf_module\n",
            "    return import_module(self.urlconf_name)\n",
            "  File \"/usr/lib/python3.9/importlib/__init__.py\", line 127, in import_module\n",
            "    return _bootstrap._gcd_import(name[level:], package, level)\n",
            "  File \"<frozen importlib._bootstrap>\", line 1030, in _gcd_import\n",
            "  File \"<frozen importlib._bootstrap>\", line 1007, in _find_and_load\n",
            "  File \"<frozen importlib._bootstrap>\", line 986, in _find_and_load_unlocked\n",
            "  File \"<frozen importlib._bootstrap>\", line 680, in _load_unlocked\n",
            "  File \"<frozen importlib._bootstrap_external>\", line 850, in exec_module\n",
            "  File \"<frozen importlib._bootstrap>\", line 228, in _call_with_frames_removed\n",
            "  File \"/content/employee_database/employee_database/urls.py\", line 18, in <module>\n",
            "    from PersonalData.views import employee_create\n",
            "  File \"/content/employee_database/PersonalData/views.py\", line 3, in <module>\n",
            "    from .forms import EmployeeForm\n",
            "  File \"/content/employee_database/PersonalData/forms.py\", line 39\n",
            "    contact_instance.save()\n",
            "                           ^\n",
            "IndentationError: unindent does not match any outer indentation level\n",
            "/content/employee_database/PersonalData/forms.py changed, reloading.\n",
            "Watching for file changes with StatReloader\n",
            "Performing system checks...\n",
            "\n",
            "System check identified no issues (0 silenced).\n",
            "March 18, 2023 - 19:37:23\n",
            "Django version 4.1.7, using settings 'employee_database.settings'\n",
            "Starting development server at http://127.0.0.1:80/\n",
            "Quit the server with CONTROL-C.\n",
            "/content/employee_database/PersonalData/forms.py changed, reloading.\n",
            "Watching for file changes with StatReloader\n",
            "Performing system checks...\n",
            "\n",
            "System check identified no issues (0 silenced).\n",
            "March 18, 2023 - 19:37:38\n",
            "Django version 4.1.7, using settings 'employee_database.settings'\n",
            "Starting development server at http://127.0.0.1:80/\n",
            "Quit the server with CONTROL-C.\n",
            "/content/employee_database/PersonalData/forms.py changed, reloading.\n",
            "Watching for file changes with StatReloader\n",
            "Performing system checks...\n",
            "\n",
            "System check identified no issues (0 silenced).\n",
            "March 18, 2023 - 19:37:43\n",
            "Django version 4.1.7, using settings 'employee_database.settings'\n",
            "Starting development server at http://127.0.0.1:80/\n",
            "Quit the server with CONTROL-C.\n",
            "Internal Server Error: /employee/create/\n",
            "Traceback (most recent call last):\n",
            "  File \"/usr/local/lib/python3.9/dist-packages/django/core/handlers/exception.py\", line 56, in inner\n",
            "    response = get_response(request)\n",
            "  File \"/usr/local/lib/python3.9/dist-packages/django/core/handlers/base.py\", line 197, in _get_response\n",
            "    response = wrapped_callback(request, *callback_args, **callback_kwargs)\n",
            "  File \"/content/employee_database/PersonalData/views.py\", line 39, in employee_create\n",
            "    form.save()\n",
            "  File \"/content/employee_database/PersonalData/forms.py\", line 29, in save\n",
            "    emergency_contact = self.cleaned_data['emergency_contact-0']\n",
            "KeyError: 'emergency_contact-0'\n",
            "[18/Mar/2023 19:37:44] \u001b[35;1m\"POST /employee/create/ HTTP/1.1\" 500 76905\u001b[0m\n",
            "[18/Mar/2023 19:37:48] \u001b[m\"GET /employee/create/ HTTP/1.1\" 200 2622\u001b[0m\n",
            "Internal Server Error: /employee/create/\n",
            "Traceback (most recent call last):\n",
            "  File \"/usr/local/lib/python3.9/dist-packages/django/core/handlers/exception.py\", line 56, in inner\n",
            "    response = get_response(request)\n",
            "  File \"/usr/local/lib/python3.9/dist-packages/django/core/handlers/base.py\", line 197, in _get_response\n",
            "    response = wrapped_callback(request, *callback_args, **callback_kwargs)\n",
            "  File \"/content/employee_database/PersonalData/views.py\", line 39, in employee_create\n",
            "    form.save()\n",
            "  File \"/content/employee_database/PersonalData/forms.py\", line 29, in save\n",
            "    emergency_contact = self.cleaned_data['emergency_contact-0']\n",
            "KeyError: 'emergency_contact-0'\n",
            "[18/Mar/2023 19:38:15] \u001b[35;1m\"POST /employee/create/ HTTP/1.1\" 500 76895\u001b[0m\n",
            "/content/employee_database/PersonalData/forms.py changed, reloading.\n",
            "Watching for file changes with StatReloader\n",
            "Performing system checks...\n",
            "\n",
            "System check identified no issues (0 silenced).\n",
            "March 18, 2023 - 19:38:24\n",
            "Django version 4.1.7, using settings 'employee_database.settings'\n",
            "Starting development server at http://127.0.0.1:80/\n",
            "Quit the server with CONTROL-C.\n",
            "/content/employee_database/PersonalData/forms.py changed, reloading.\n",
            "Watching for file changes with StatReloader\n",
            "Performing system checks...\n",
            "\n",
            "System check identified no issues (0 silenced).\n",
            "March 18, 2023 - 19:38:28\n",
            "Django version 4.1.7, using settings 'employee_database.settings'\n",
            "Starting development server at http://127.0.0.1:80/\n",
            "Quit the server with CONTROL-C.\n",
            "[18/Mar/2023 19:38:32] \u001b[m\"GET /employee/create/ HTTP/1.1\" 200 2622\u001b[0m\n",
            "Internal Server Error: /employee/create/\n",
            "Traceback (most recent call last):\n",
            "  File \"/usr/local/lib/python3.9/dist-packages/django/core/handlers/exception.py\", line 56, in inner\n",
            "    response = get_response(request)\n",
            "  File \"/usr/local/lib/python3.9/dist-packages/django/core/handlers/base.py\", line 197, in _get_response\n",
            "    response = wrapped_callback(request, *callback_args, **callback_kwargs)\n",
            "  File \"/content/employee_database/PersonalData/views.py\", line 39, in employee_create\n",
            "    form.save()\n",
            "  File \"/content/employee_database/PersonalData/forms.py\", line 29, in save\n",
            "    emergency_contact = self.cleaned_data['emergency_contact']\n",
            "KeyError: 'emergency_contact'\n",
            "[18/Mar/2023 19:38:54] \u001b[35;1m\"POST /employee/create/ HTTP/1.1\" 500 76882\u001b[0m\n",
            "/content/employee_database/PersonalData/forms.py changed, reloading.\n",
            "Watching for file changes with StatReloader\n",
            "Performing system checks...\n",
            "\n",
            "System check identified no issues (0 silenced).\n",
            "March 18, 2023 - 19:39:09\n",
            "Django version 4.1.7, using settings 'employee_database.settings'\n",
            "Starting development server at http://127.0.0.1:80/\n",
            "Quit the server with CONTROL-C.\n",
            "/content/employee_database/PersonalData/models.py changed, reloading.\n",
            "Watching for file changes with StatReloader\n",
            "Performing system checks...\n",
            "\n",
            "System check identified no issues (0 silenced).\n",
            "March 18, 2023 - 19:39:24\n",
            "Django version 4.1.7, using settings 'employee_database.settings'\n",
            "Starting development server at http://127.0.0.1:80/\n",
            "Quit the server with CONTROL-C.\n",
            "/content/employee_database/PersonalData/models.py changed, reloading.\n",
            "Watching for file changes with StatReloader\n",
            "Performing system checks...\n",
            "\n",
            "System check identified no issues (0 silenced).\n",
            "March 18, 2023 - 19:45:28\n",
            "Django version 4.1.7, using settings 'employee_database.settings'\n",
            "Starting development server at http://127.0.0.1:80/\n",
            "Quit the server with CONTROL-C.\n",
            "/content/employee_database/PersonalData/models.py changed, reloading.\n",
            "Watching for file changes with StatReloader\n",
            "Performing system checks...\n",
            "\n",
            "System check identified no issues (0 silenced).\n",
            "March 18, 2023 - 19:45:37\n",
            "Django version 4.1.7, using settings 'employee_database.settings'\n",
            "Starting development server at http://127.0.0.1:80/\n",
            "Quit the server with CONTROL-C.\n",
            "/content/employee_database/PersonalData/models.py changed, reloading.\n",
            "Watching for file changes with StatReloader\n",
            "Performing system checks...\n",
            "\n",
            "System check identified no issues (0 silenced).\n",
            "March 18, 2023 - 19:45:42\n",
            "Django version 4.1.7, using settings 'employee_database.settings'\n",
            "Starting development server at http://127.0.0.1:80/\n",
            "Quit the server with CONTROL-C.\n",
            "/content/employee_database/PersonalData/models.py changed, reloading.\n",
            "Watching for file changes with StatReloader\n",
            "Performing system checks...\n",
            "\n",
            "System check identified no issues (0 silenced).\n",
            "March 18, 2023 - 20:36:27\n",
            "Django version 4.1.7, using settings 'employee_database.settings'\n",
            "Starting development server at http://127.0.0.1:80/\n",
            "Quit the server with CONTROL-C.\n"
          ]
        }
      ]
    },
    {
      "cell_type": "code",
      "source": [
        "!zip employee_database"
      ],
      "metadata": {
        "id": "WrsyeYkjcEYG",
        "outputId": "4ed7dd21-e869-4c43-fd5e-98d8132da179",
        "colab": {
          "base_uri": "https://localhost:8080/"
        }
      },
      "execution_count": 7,
      "outputs": [
        {
          "output_type": "stream",
          "name": "stdout",
          "text": [
            "\n",
            "zip error: Nothing to do! (employee_database.zip)\n"
          ]
        }
      ]
    }
  ]
}